<?xml version="1.0"?>
<robot name="my_robot">

    <material name="blue"><color rgba="0 0 1 1"/></material>
    <material name="black"><color rgba="0 0 0 1"/></material>
    <material name="red"><color rgba="1 0 0 1"/></material>

    <link name="base_link">
        <visual>
            <origin xyz="0 0 0.1" rpy="0 0 0"/>
            <geometry><box size="0.4 0.3 0.1"/></geometry>
            <material name="blue"/>
        </visual>
        <collision>
            <origin xyz="0 0 0.1" rpy="0 0 0"/>
            <geometry><box size="0.4 0.3 0.1"/></geometry>
        </collision>
        <inertial>
            <mass value="5.0"/>
            <inertia ixx="0.1" ixy="0" ixz="0" iyy="0.1" iyz="0" izz="0.1"/>
        </inertial>
    </link>

    <link name="left_wheel">
        <visual>
            <geometry><cylinder radius="0.1" length="0.05"/></geometry>
            <material name="black"/>
        </visual>
        <collision>
            <geometry><cylinder radius="0.1" length="0.05"/></geometry>
        </collision>
        <inertial>
            <mass value="0.5"/>
            <inertia ixx="0.01" ixy="0" ixz="0" iyy="0.01" iyz="0" izz="0.01"/>
        </inertial>
    </link>

    <joint name="base_to_left_wheel" type="continuous">
        <parent link="base_link"/><child link="left_wheel"/>
        <origin xyz="-0.1 0.175 0.1" rpy="1.5708 0 0"/><axis xyz="0 0 1"/>
    </joint>

    <link name="right_wheel">
        <visual>
            <geometry><cylinder radius="0.1" length="0.05"/></geometry>
            <material name="black"/>
        </visual>
        <collision>
            <geometry><cylinder radius="0.1" length="0.05"/></geometry>
        </collision>
        <inertial>
            <mass value="0.5"/>
            <inertia ixx="0.01" ixy="0" ixz="0" iyy="0.01" iyz="0" izz="0.01"/>
        </inertial>
    </link>

    <joint name="base_to_right_wheel" type="continuous">
        <parent link="base_link"/><child link="right_wheel"/>
        <origin xyz="-0.1 -0.175 0.1" rpy="1.5708 0 0"/><axis xyz="0 0 1"/>
    </joint>

    <link name="laser_frame">
        <visual>
            <geometry><cylinder radius="0.05" length="0.04"/></geometry>
            <material name="red"/>
        </visual>
    </link>

    <joint name="laser_joint" type="fixed">
        <parent link="base_link"/><child link="laser_frame"/>
        <origin xyz="0.1 0 0.17" rpy="0 0 0"/>
    </joint>

    <gazebo>
        <plugin name="gz::sim::systems::DiffDrive" filename="gz-sim-diff-drive-system">
            <left_joint>base_to_left_wheel</left_joint>
            <right_joint>base_to_right_wheel</right_joint>
            <wheel_separation>0.35</wheel_separation>
            <wheel_radius>0.1</wheel_radius>
            <topic>/cmd_vel</topic> </plugin>
    </gazebo>

</robot>